
<!-- xml file for biped  -->

<mujoco>
    <option gravity = "0 0 -10" />

    <asset>
        <texture type="skybox" builtin="gradient" rgb1=".3 .5 .7" rgb2="0 0 0" width="32" height="512"/>
        <texture name="body" type="cube" builtin="flat" mark="cross" width="128" height="128" rgb1="0.8 0.6 0.4" rgb2="0.8 0.6 0.4" markrgb="1 1 1" random="0.01"/>
        <material name="body" texture="body" texuniform="true" rgba="0.8 0.6 .4 1"/>
        <texture name="grid" type="2d" builtin="checker" width="512" height="512" rgb1=".1 .2 .3" rgb2=".2 .3 .4"/>
        <material name="grid" texture="grid" texrepeat="1 1" texuniform="true" reflectance=".2"/>
    </asset>


    
    <worldbody>
        <geom name="floor" size="0 0 .05" type="plane" material="grid" condim="3"/>
        <body name="torso1" pos="0 0 4" euler="0 90 0">
            <freejoint name="root"/>
            <geom type="capsule" size="0.2 0.4" rgba="0 0 1 1" mass="4"/>

            <body name="torso2" pos="0.4 0 0" euler="0 0 0">
                <geom type="capsule" size="0.2 0.4" rgba="0 0 1 1" mass="4"/>

                <body name="torso3" pos="0.4 0 0" euler="0 0 0">
                <geom type="capsule" size="0.2 0.4" rgba="0 0 1 1" mass="4"/>

                    <body name= "leftThigh" pos="0.8 0 -0.4" euler="90 -90 0">
                        <joint name="hipLeft" type="hinge" axis = "0 1 0" pos = "0 0 0.4"/>
                        <geom type="capsule" size="0.2 0.4" rgba="1 0 0 1" mass="1"/>

                        <body name= "leftShin" pos="0 0 -1.2" euler="0 0 0">
                            <joint name="kneeLeft" type="hinge" axis = "0 1 0" pos = "0 0 0.6"/>
                            <geom type="capsule" size="0.2 0.4" rgba="1 0 0 1" mass="1"/>
                        
                            <!-- <body name="leftFoot" pos="0 0 0.8" euler="0 0 0">
                                <geom type="sphere" size="0.2" rgba="1 1 0 1" mass="0.25"/>
                            </body> -->
                    
                        </body>

                        
                    </body>
            

                    <body name= "rightThigh" pos="0.8 0 0.4" euler="90 -90 0">
                        <joint name="hipRight" type="hinge" axis = "0 1 0" pos = "0 0 0.4"/>
                        <geom type="capsule" size="0.2 0.4" rgba="1 0 0 1" mass="1"/>

                        <body name= "rightShin" pos="0 0 -1.2" euler="0 0 0">
                            <joint name="kneeRight" type="hinge" axis = "0 1 0" pos = "0 0 0.6"/>
                            <geom type="capsule" size="0.2 0.4" rgba="1 0 0 1" mass="1"/>
                        
                            <!-- <body name="rightFoot" pos="0 0 0.8" euler="0 0 0">
                                <geom type="sphere" size="0.2" rgba="1 1 0 1" mass="0.25"/>
                            </body> -->
                        
                        </body>
                    </body> 
                </body>
            </body>

            <body name="head" pos="-0.4 0 0" euler="0 0 0">
                <geom type="sphere" size="0.2" rgba="1 1 1 1" mass="4"/>
            </body>

        </body>
    </worldbody>

   <actuator>
        <motor name="torqueL0" joint="hipLeft"   gear="1" />
        <motor name="torqueL1" joint="kneeLeft"  gear="1" />
        <motor name="torqueR0" joint="hipRight"  gear="1" />
        <motor name="torqueR1" joint="kneeRight"  gear="1" />
   </actuator>

    <!-- <sensor>
        <accelerometer name="imu_accel" site="torso1"/>
        <gyro name="imu_gyro"           site="torso1"/>
        <velocimeter name="velocimeter" site="torso1"/>
    </sensor> -->

</mujoco>