
<!-- xml file for biped  -->

<mujoco>
    <option gravity = "0 0 -10" />

    <asset>
        <texture type="skybox" builtin="gradient" rgb1=".3 .5 .7" rgb2="0 0 0" width="32" height="512"/>
        <texture name="body" type="cube" builtin="flat" mark="cross" width="128" height="128" rgb1="0.8 0.6 0.4" rgb2="0.8 0.6 0.4" markrgb="1 1 1" random="0.01"/>
        <material name="body" texture="body" texuniform="true" rgba="0.8 0.6 .4 1"/>
        <texture name="grid" type="2d" builtin="checker" width="512" height="512" rgb1=".1 .2 .3" rgb2=".2 .3 .4"/>
        <material name="grid" texture="grid" texrepeat="1 1" texuniform="true" reflectance=".2"/>
    </asset>


    <!-- <worldbody>
        <light diffuse="0 0 0" pos="0 0 10" dir="0 0 -1"/>
        <body pos="0 0 0" euler="0 0 0">
            <geom type="box" size="1 1 0.2" rgba="0 0 1 1" mass="4"/>
        </body>    

        
        <body pos="0 0 0" euler="0 0 0">
            <geom type="cylinder" size="0.05 0.5" rgba="1 0 0 1" mass="1"/>
            <joint name="hipLeft" type="hinge" axis = "0 -1 0" pos = "0 0 0.5"/>
            

               
        </body>
        <body pos="0 0 -1" euler="0 0 0">
            <geom type="cylinder" size="0.05 0.5" rgba="0 1 0 1" mass="1"/>
            <joint name="kneeLeft" type="hinge" axis = "0 -1 0" pos = "0 0 0.5"/>
        </body> 
    </worldbody> -->
    <worldbody>
        <geom name="floor" size="0 0 .05" type="plane" material="grid" condim="3"/>
        <body name="torso" pos="0 0 0.75" euler="90 0 0">
            <freejoint name="root"/>
            <geom type="box" size="0.5 0.75 0.2" rgba="0 0 1 1" mass="4"/>
            <body name= "leftLeg" pos="-0.5 0 0" euler="90 0 0">
                <joint name="kneeLeft" type="hinge" axis = "1 0 0" pos = "0 0 0.5"/>
                <geom type="capsule" size="0.2 0.4" rgba="1 0 0 1" mass="1"/>
            </body>
            <body name= "rightLeg" pos="0.5 0 0" euler="90 0 0">
                <joint name="kneeRight" type="hinge" axis = "1 0 0" pos = "0 0 0.75"/>
                <geom type="capsule" size="0.2 0.4" rgba="1 0 0 1" mass="1"/>
            </body> 
        </body>
    </worldbody>

   <!-- <actuator>
     <motor name="torque0" joint="hipLeft"  gear="1" />
     <motor name="torque1" joint="kneeLeft"  gear="1" />
   </actuator> -->

</mujoco>